Workbook

Sheet FRAN 1
B1: PEDIDOS POR BASE | O1: CUBICAJE DE TU PEDIDO POR BASE
A2: CODIGO | B2: DENOMINACION | C2: CANTIDAD | D2: suma | E2: CUBICAJE A LA CARTA | F2: TOTAL PRECIO | G2: IVA | H2: PESO UNITARIO | I2: TOTAL PESO | J2: BASES | K2: FAMILIA DE PRODUCTOS | L2: CUBICAJE | M2: TOTAL | O2: CUBICAJE TOTAL | Q2: PALLET | S2: LINEA DE PRODUCTOS | V2: CANT. | W2: BASES | X2: CUBICAJE | Y2: CANT.X BASE | Z2: cubicaje x base
A3: 4000062 | B3: ANANA A LA CREMA 7,800 KG GRIDO | C3: 1 | D3: =SUM(C3:C40) | E3: =VLOOKUP(A3,MATERIALES!A497:D591,4,0) | F3: =E3*C3 | G3: =F3*1.21 | H3: =VLOOKUP(A3,MATERIALES!$A:$E,5,0) | I3: =C3*H3 | J3: 25 | K3: GRANEL | L3: =VLOOKUP(A3,MATERIALES!$A:$D,4,0) | M3: =L3*C3 | N3: % | O3: =SUM(X3:X13) | Q3: {=_xlfn.IFS(O3<=100,1,O3<=200,2,O3<=300,3,O3<=400,4,O3<=500,5,O3<=600,6,O3<=700,7,O3<=800,8,O3<=900,9,O3<=1000,10,O3<=1100,11,O3<=1200,12,O3<=1300,13,O3<=1400,14,O3<=1500,15,O3<=1600,16,O3<=1700,17,O3<=1800,18,O3<=1900,19,O3<=2000,20,O3<=2100,21,O3<=2200,22,O3<=2300,23,O3<=2400,24,O3<=2500,25,O3<=2600,26,O3<=2700,27,O3<=2800,28)} | R3: =Q3 | S3: GRANEL | V3: =SUMIF($K:$K,S3,$C:$C) | W3: =V3/25 | X3: =SUMIF($K:$K,S3,$M:$M) | Y3: 25 | Z3: 0.2
A4: 4000048 | B4: BANANA C/DULC LECHE 7,800 KG GRIDO | C4: 13 | E4: =VLOOKUP(A4,MATERIALES!A498:D592,4,0) | F4: =E4*C4 | G4: =F4*1.21 | H4: =VLOOKUP(A4,MATERIALES!$A:$E,5,0) | I4: =C4*H4 | K4: GRANEL | L4: =VLOOKUP(A4,MATERIALES!$A:$D,4,0) | M4: =L4*C4 | S4: POTES 3L | V4: =SUMIF($K:$K,S4,$C:$C) | W4: =V4/15 | X4: =SUMIF($K:$K,S4,$M:$M) | Y4: 15 | Z4: 0.1635
A5: 4000608 | B5: CANDY 7,800 KG GRIDO | C5: 0 | E5: =VLOOKUP(A5,MATERIALES!A499:D593,4,0) | F5: =E5*C5 | G5: =F5*1.21 | H5: =VLOOKUP(A5,MATERIALES!$A:$E,5,0) | I5: =C5*H5 | K5: GRANEL | L5: =VLOOKUP(A5,MATERIALES!$A:$D,4,0) | M5: =L5*C5 | O5: KILOS | S5: TORTAS | V5: =SUMIF($K:$K,S5,$C:$C) | W5: =V5/10 | X5: =SUMIF($K:$K,S5,$M:$M) | Y5: 10 | Z5: 0.12
A6: 4000193 | B6: CAPPUCCINO GRANIZADO 7,800 KG GRIDO | C6: 2 | E6: =VLOOKUP(A6,MATERIALES!A500:D594,4,0) | F6: =E6*C6 | G6: =F6*1.21 | H6: =VLOOKUP(A6,MATERIALES!$A:$E,5,0) | I6: =C6*H6 | K6: GRANEL | L6: =VLOOKUP(A6,MATERIALES!$A:$D,4,0) | M6: =L6*C6 | O6: =SUM(I3:I113) | S6: TENTACION | V6: =SUMIF($K:$K,S6,$C:$C) | W6: =V6/15 | X6: =SUMIF($K:$K,S6,$M:$M) | Y6: 15 | Z6: 0.0765
A7: 4000070 | B7: CEREZA 7,800 KG - GRIDO | C7: 6 | E7: =VLOOKUP(A7,MATERIALES!A501:D595,4,0) | F7: =E7*C7 | G7: =F7*1.21 | H7: =VLOOKUP(A7,MATERIALES!$A:$E,5,0) | I7: =C7*H7 | K7: GRANEL | L7: =VLOOKUP(A7,MATERIALES!$A:$D,4,0) | M7: =L7*C7 | S7: PALITOS | V7: =SUMIF($K:$K,S7,$C:$C) | W7: =V7/15 | X7: =SUMIF($K:$K,S7,$M:$M) | Y7: 15 | Z7: 0.123
A8: 4000827 | B8: CHOCO BLANCO OREO 7,800 KG GRIDO | C8: 6 | E8: =VLOOKUP(A8,MATERIALES!A502:D596,4,0) | F8: =E8*C8 | G8: =F8*1.21 | H8: =VLOOKUP(A8,MATERIALES!$A:$E,5,0) | I8: =C8*H8 | K8: GRANEL | L8: =VLOOKUP(A8,MATERIALES!$A:$D,4,0) | M8: =L8*C8 | O8: CUBICAJE A LA CARTA | Q8: PALLET | S8: PALITOS NUEVOS X 10 UNID | V8: =SUMIF($K:$K,S8,$C:$C) | W8: =V8/12 | X8: =SUMIF($K:$K,S8,$M:$M) | Y8: 12 | Z8: 0.1666
A9: 4000043 | B9: CHOCOLATE 7,800 KG GRIDO | C9: 22 | E9: =VLOOKUP(A9,MATERIALES!A503:D597,4,0) | F9: =E9*C9 | G9: =F9*1.21 | H9: =VLOOKUP(A9,MATERIALES!$A:$E,5,0) | I9: =C9*H9 | K9: GRANEL | L9: =VLOOKUP(A9,MATERIALES!$A:$D,4,0) | M9: =L9*C9 | N9: % | O9: =SUM(F3:F130) | Q9: {=_xlfn.IFS(O9<=100,1,O9<=200,2,O9<=300,3,O9<=400,4,O9<=500,5,O9<=600,6,O9<=700,7,O9<=800,8,O9<=900,9,O9<=1000,10,O9<=1100,11,O9<=1200,12,O9<=1300,13,O9<=1400,14,O9<=1500,15,O9<=1600,16,O9<=1700,17,O9<=1800,18,O9<=1900,19,O9<=2000,20,O9<=2100,21,O9<=2200,22,O9<=2300,23,O9<=2400,24,O9<=2500,25,O9<=2600,26,O9<=2700,27,O9<=2800,28)} | S9: ESCOCES-SHOT-SECRETO | V9: =SUMIF($K:$K,S9,$C:$C) | W9: =V9/10 | X9: =SUMIF($K:$K,S9,$M:$M) | Y9: 10 | Z9: 0.077
A10: 4000059 | B10: CHOCOLATE BLANCO 7,800 KG GRIDO | C10: 3 | E10: =VLOOKUP(A10,MATERIALES!A504:D598,4,0) | F10: =E10*C10 | G10: =F10*1.21 | H10: =VLOOKUP(A10,MATERIALES!$A:$E,5,0) | I10: =C10*H10 | K10: GRANEL | L10: =VLOOKUP(A10,MATERIALES!$A:$D,4,0) | M10: =L10*C10 | S10: PORCION | V10: =SUMIF($K:$K,S10,$C:$C) | W10: =V10/10 | X10: =SUMIF($K:$K,S10,$M:$M) | Y10: 10 | Z10: 0.077
A11: 4000067 | B11: CHOCOLATE C/ALMEN 7,800 KG GRIDO | C11: 13 | E11: =VLOOKUP(A11,MATERIALES!A505:D599,4,0) | F11: =E11*C11 | G11: =F11*1.21 | H11: =VLOOKUP(A11,MATERIALES!$A:$E,5,0) | I11: =C11*H11 | K11: GRANEL | L11: =VLOOKUP(A11,MATERIALES!$A:$D,4,0) | M11: =L11*C11 | S11: BARRAS | V11: =SUMIF($K:$K,S11,$C:$C) | W11: =V11/12 | X11: =SUMIF($K:$K,S11,$M:$M) | Y11: 12 | Z11: 0.0696
A12: 4000061 | B12: CHOCOLATE MANI CRUNCH 7,800 KG GRIDO | C12: 0 | E12: =VLOOKUP(A12,MATERIALES!A506:D600,4,0) | F12: =E12*C12 | G12: =F12*1.21 | H12: =VLOOKUP(A12,MATERIALES!$A:$E,5,0) | I12: =C12*H12 | K12: GRANEL | L12: =VLOOKUP(A12,MATERIALES!$A:$D,4,0) | M12: =L12*C12 | S12: ALIM.CONGELADOS CAJAS GRANDES | T12: =SUMIF(#REF!,"C",C83:C113) | U12: 16.668 | V12: =SUMIF($K:$K,S12,$C:$C) | W12: =V12/5 | X12: =SUMIF($K:$K,S12,$M:$M) | Y12: 5 | Z12: 0.06
A13: 4000057 | B13: CHOCOLATE SUIZO 7,800 KG GRIDO | C13: 3 | E13: =VLOOKUP(A13,MATERIALES!A507:D601,4,0) | F13: =E13*C13 | G13: =F13*1.21 | H13: =VLOOKUP(A13,MATERIALES!$A:$E,5,0) | I13: =C13*H13 | K13: GRANEL | L13: =VLOOKUP(A13,MATERIALES!$A:$D,4,0) | M13: =L13*C13 | N13: COMPARATIVO CON RESPECTO AL CUBICAJE DE PEDIDOS A LA CARTA | S13: ALIM.CONGELADOS CAJAS CHICAS | V13: =SUMIF($K:$K,S13,$C:$C) | W13: =V13/5 | X13: =SUMIF($K:$K,S13,$M:$M) | Y13: 5 | Z13: 0.03
A14: 4000045 | B14: CREMA AMERICANA 7,800 KG GRIDO | C14: 17 | E14: =VLOOKUP(A14,MATERIALES!A508:D602,4,0) | F14: =E14*C14 | G14: =F14*1.21 | H14: =VLOOKUP(A14,MATERIALES!$A:$E,5,0) | I14: =C14*H14 | K14: GRANEL | L14: =VLOOKUP(A14,MATERIALES!$A:$D,4,0) | M14: =L14*C14 | S14: BULTOS | V14: =SUM(V3:V13) | W14: =O3 | X14: =110-W14 | AA14: =$O$3 | AB14: =IF(AA14<100,0,O3) | AD14: =IF(AB14<100,0,101) | AE14: =Z15-AA14 | AF14: =100-AE14 | AG14: =AE14
A15: 4000051 | B15: CREMA COOKIE 7,800 KG GRIDO | C15: 9 | E15: =VLOOKUP(A15,MATERIALES!A509:D603,4,0) | F15: =E15*C15 | G15: =F15*1.21 | H15: =VLOOKUP(A15,MATERIALES!$A:$E,5,0) | I15: =C15*H15 | K15: GRANEL | L15: =VLOOKUP(A15,MATERIALES!$A:$D,4,0) | M15: =L15*C15 | Z15: 200 | AA15: =$O$3 | AB15: =IF(AA15<200,0,$O$3) | AD15: =IF(AB15<100,0,101) | AE15: =Z16-AA15 | AF15: =100-AE15 | AG15: =AE15
A16: 4000066 | B16: CREMA RUSA 7,800 KG GRIDO | C16: 2 | E16: =VLOOKUP(A16,MATERIALES!A510:D604,4,0) | F16: =E16*C16 | G16: =F16*1.21 | H16: =VLOOKUP(A16,MATERIALES!$A:$E,5,0) | I16: =C16*H16 | K16: GRANEL | L16: =VLOOKUP(A16,MATERIALES!$A:$D,4,0) | M16: =L16*C16 | O16: DIFERENCIA ENTRE MODALIDADES | S16: BASES | V16: =SUM(W3:W12) | Z16: 300 | AA16: =$O$3 | AB16: =IF(AA16<300,0,$O$3) | AD16: =IF(AB16<100,0,101) | AE16: =Z17-AA16 | AF16: =100-AE16 | AG16: =AE16
A17: 4000041 | B17: DULCE DE LECHE 7,800 KG GRIDO | C17: 21 | E17: =VLOOKUP(A17,MATERIALES!A511:D605,4,0) | F17: =E17*C17 | G17: =F17*1.21 | H17: =VLOOKUP(A17,MATERIALES!$A:$E,5,0) | I17: =C17*H17 | K17: GRANEL | L17: =VLOOKUP(A17,MATERIALES!$A:$D,4,0) | M17: =L17*C17 | N17: % | O17: =O9-O3 | Z17: 400 | AA17: =$O$3 | AB17: =IF(AA17<400,0,$O$3) | AD17: =IF(AB17<100,0,101) | AE17: =Z18-AA17 | AF17: =100-AE17 | AG17: =AE17
A18: 4000069 | B18: DULCE LECHE C/BROWNIE 7,800 KG GRIDO | C18: 0 | E18: =VLOOKUP(A18,MATERIALES!A512:D606,4,0) | F18: =E18*C18 | G18: =F18*1.21 | H18: =VLOOKUP(A18,MATERIALES!$A:$E,5,0) | I18: =C18*H18 | K18: GRANEL | L18: =VLOOKUP(A18,MATERIALES!$A:$D,4,0) | M18: =L18*C18 | Z18: 500 | AA18: =$O$3 | AB18: =IF(AA18<400,0,$O$3) | AD18: =IF(AB18<100,0,101) | AE18: =Z19-AA18 | AF18: =100-AE18 | AG18: =AE18
A19: 4000068 | B19: DULCE LECHE C/NUEZ 7,800 KG GRIDO | C19: 1 | E19: =VLOOKUP(A19,MATERIALES!A513:D607,4,0) | F19: =E19*C19 | G19: =F19*1.21 | H19: =VLOOKUP(A19,MATERIALES!$A:$E,5,0) | I19: =C19*H19 | K19: GRANEL | L19: =VLOOKUP(A19,MATERIALES!$A:$D,4,0) | M19: =L19*C19 | Z19: 600 | AA19: =$O$3 | AB19: =IF(AA19<400,0,$O$3) | AD19: =IF(AB19<100,0,101) | AE19: =Z20-AA19 | AF19: =100-AE19 | AG19: =AE19
A20: 4000046 | B20: DULCE LECHE GRANIZADO 7,800 KG GRIDO | C20: 22 | E20: =VLOOKUP(A20,MATERIALES!A514:D608,4,0) | F20: =E20*C20 | G20: =F20*1.21 | H20: =VLOOKUP(A20,MATERIALES!$A:$E,5,0) | I20: =C20*H20 | K20: GRANEL | L20: =VLOOKUP(A20,MATERIALES!$A:$D,4,0) | M20: =L20*C20 | Z20: 700 | AA20: =$O$3 | AB20: =IF(AA20<400,0,$O$3) | AD20: =IF(AB20<100,0,101) | AE20: =Z21-AA20 | AF20: =100-AE20 | AG20: =AE20
A21: 4000316 | B21: DURAZNO A LA CREMA 7,800 KG GRIDO | C21: 0 | E21: =VLOOKUP(A21,MATERIALES!A515:D609,4,0) | F21: =E21*C21 | G21: =F21*1.21 | H21: =VLOOKUP(A21,MATERIALES!$A:$E,5,0) | I21: =C21*H21 | K21: GRANEL | L21: =VLOOKUP(A21,MATERIALES!$A:$D,4,0) | M21: =L21*C21 | Z21: 800 | AA21: =$O$3 | AB21: =IF(AA21<400,0,$O$3) | AD21: =IF(AB21<100,0,101) | AE21: =Z22-AA21 | AF21: =100-AE21 | AG21: =AE21
A22: 4000047 | B22: FLAN 7,800 KG GRIDO | C22: 4 | E22: =VLOOKUP(A22,MATERIALES!A516:D610,4,0) | F22: =E22*C22 | G22: =F22*1.21 | H22: =VLOOKUP(A22,MATERIALES!$A:$E,5,0) | I22: =C22*H22 | K22: GRANEL | L22: =VLOOKUP(A22,MATERIALES!$A:$D,4,0) | M22: =L22*C22 | Z22: 900 | AA22: =$O$3 | AB22: =IF(AA22<400,0,$O$3) | AD22: =IF(AB22<100,0,101) | AE22: =Z23-AA22 | AF22: =100-AE22 | AG22: =AE22
A23: 4000042 | B23: FRUTILLA A LA CREMA 7,800KG GRIDO | C23: 22 | E23: =VLOOKUP(A23,MATERIALES!A517:D611,4,0) | F23: =E23*C23 | G23: =F23*1.21 | H23: =VLOOKUP(A23,MATERIALES!$A:$E,5,0) | I23: =C23*H23 | K23: GRANEL | L23: =VLOOKUP(A23,MATERIALES!$A:$D,4,0) | M23: =L23*C23 | Z23: 1000 | AA23: =$O$3 | AB23: =IF(AA23<400,0,$O$3) | AD23: =IF(AB23<100,0,101) | AE23: =Z24-AA23 | AF23: =100-AE23 | AG23: =AE23
A24: 4000194 | B24: FRUTILLA AL AGUA 7,800 KG GRIDO | C24: 0 | E24: =VLOOKUP(A24,MATERIALES!A518:D612,4,0) | F24: =E24*C24 | G24: =F24*1.21 | H24: =VLOOKUP(A24,MATERIALES!$A:$E,5,0) | I24: =C24*H24 | K24: GRANEL | L24: =VLOOKUP(A24,MATERIALES!$A:$D,4,0) | M24: =L24*C24 | Z24: 1100 | AA24: =$O$3 | AB24: =IF(AA24<400,0,$O$3) | AD24: =IF(AB24<100,0,101) | AE24: =Z25-AA24 | AF24: =100-AE24 | AG24: =AE24
A25: 4000607 | B25: FRUTOS ROJOS AL AGUA 7,800 KG GRIDO | C25: 2 | E25: =VLOOKUP(A25,MATERIALES!A519:D613,4,0) | F25: =E25*C25 | G25: =F25*1.21 | H25: =VLOOKUP(A25,MATERIALES!$A:$E,5,0) | I25: =C25*H25 | K25: GRANEL | L25: =VLOOKUP(A25,MATERIALES!$A:$D,4,0) | M25: =L25*C25 | Z25: 1200 | AA25: =$O$3 | AB25: =IF(AA25<400,0,$O$3) | AD25: =IF(AB25<100,0,101) | AE25: =Z26-AA25 | AF25: =100-AE25 | AG25: =AE25
A26: 4000040 | B26: GRANIZADO 7,800 KG GRIDO | C26: 11 | E26: =VLOOKUP(A26,MATERIALES!A520:D614,4,0) | F26: =E26*C26 | G26: =F26*1.21 | H26: =VLOOKUP(A26,MATERIALES!$A:$E,5,0) | I26: =C26*H26 | K26: GRANEL | L26: =VLOOKUP(A26,MATERIALES!$A:$D,4,0) | M26: =L26*C26 | Z26: 1300 | AA26: =$O$3 | AB26: =IF(AA26<400,0,$O$3) | AD26: =IF(AB26<100,0,101) | AE26: =Z27-AA26 | AF26: =100-AE26 | AG26: =AE26
A27: 4000056 | B27: KINOTOS AL WHISKY 7,800 KG GRIDO | C27: 0 | E27: =VLOOKUP(A27,MATERIALES!A521:D615,4,0) | F27: =E27*C27 | G27: =F27*1.21 | H27: =VLOOKUP(A27,MATERIALES!$A:$E,5,0) | I27: =C27*H27 | K27: GRANEL | L27: =VLOOKUP(A27,MATERIALES!$A:$D,4,0) | M27: =L27*C27 | Z27: 1400 | AA27: =$O$3 | AB27: =IF(AA27<400,0,$O$3) | AD27: =IF(AB27<100,0,101) | AE27: =Z28-AA27 | AF27: =100-AE27 | AG27: =AE27
A28: 4000036 | B28: LIMON AL AGUA 7,800 KG GRIDO | C28: 5 | E28: =VLOOKUP(A28,MATERIALES!A522:D616,4,0) | F28: =E28*C28 | G28: =F28*1.21 | H28: =VLOOKUP(A28,MATERIALES!$A:$E,5,0) | I28: =C28*H28 | K28: GRANEL | L28: =VLOOKUP(A28,MATERIALES!$A:$D,4,0) | M28: =L28*C28 | Z28: 1500 | AA28: =$O$3 | AB28: =IF(AA28<400,0,$O$3) | AD28: =IF(AB28<100,0,101) | AE28: =Z29-AA28 | AF28: =100-AE28 | AG28: =AE28
A29: 4000038 | B29: MARACUYA AL AGUA 7,800 KG GRIDO | C29: 3 | E29: =VLOOKUP(A29,MATERIALES!A523:D617,4,0) | F29: =E29*C29 | G29: =F29*1.21 | H29: =VLOOKUP(A29,MATERIALES!$A:$E,5,0) | I29: =C29*H29 | K29: GRANEL | L29: =VLOOKUP(A29,MATERIALES!$A:$D,4,0) | M29: =L29*C29 | Z29: 1600 | AA29: =$O$3 | AB29: =IF(AA29<400,0,$O$3) | AD29: =IF(AB29<100,0,101) | AE29: =Z30-AA29 | AF29: =100-AE29 | AG29: =AE29
... A32: 4000049 | B32: MENTA GRANIZADA 7,800 KG GRIDO | C32: 9 | E32: =VLOOKUP(A32,MATERIALES!A526:D620,4,0) | F32: =E32*C32 | G32: =F32*1.21 | H32: =VLOOKUP(A32,MATERIALES!$A:$E,5,0) | I32: =C32*H32 | K32: GRANEL | L32: =VLOOKUP(A32,MATERIALES!$A:$D,4,0) | M32: =L32*C32 | Z32: 1900 | AA32: =$O$3 | AB32: =IF(AA32<400,0,$O$3) | AD32: =IF(AB32<100,0,101) | AE32: =Z33-AA32 | AF32: =100-AE32 | AG32: =AE32
A33: 4000039 | B33: NARANJA AL AGUA 12 7,800 KG GRIDO | C33: 1 | E33: =VLOOKUP(A33,MATERIALES!A527:D621,4,0) | F33: =E33*C33 | G33: =F33*1.21 | H33: =VLOOKUP(A33,MATERIALES!$A:$E,5,0) | I33: =C33*H33 | K33: GRANEL | L33: =VLOOKUP(A33,MATERIALES!$A:$D,4,0) | M33: =L33*C33 | Z33: 2000
A34: 4000754 | B34: PISTACHO 7,800 KG GRIDO | C34: 0 | E34: =VLOOKUP(A34,MATERIALES!A528:D622,4,0) | F34: =E34*C34 | G34: =F34*1.21 | H34: =VLOOKUP(A34,MATERIALES!$A:$E,5,0) | I34: =C34*H34 | K34: GRANEL | L34: =VLOOKUP(A34,MATERIALES!$A:$D,4,0) | M34: =L34*C34 | AA34: =$O$3 | AB34: =IF(AA34<400,0,$O$3) | AD34: =IF(AB34<100,0,101) | AE34: =Z35-AA34 | AF34: =100-AE34 | AG34: =AE34
A35: 4000065 | B35: SAMBAYON 7,800 KG GRIDO | C35: 0 | E35: =VLOOKUP(A35,MATERIALES!A529:D623,4,0) | F35: =E35*C35 | G35: =F35*1.21 | H35: =VLOOKUP(A35,MATERIALES!$A:$E,5,0) | I35: =C35*H35 | K35: GRANEL | L35: =VLOOKUP(A35,MATERIALES!$A:$D,4,0) | M35: =L35*C35 | Z35: 2100 | AA35: =$O$3 | AB35: =IF(AA35<400,0,$O$3) | AD35: =IF(AB35<100,0,101) | AE35: =Z36-AA35 | AF35: =100-AE35 | AG35: =AE35
A36: 4000064 | B36: SUPER DULCE DE LECHE 7,800 KG GRIDO | C36: 7 | E36: =VLOOKUP(A36,MATERIALES!A530:D624,4,0) | F36: =E36*C36 | G36: =F36*1.21 | H36: =VLOOKUP(A36,MATERIALES!$A:$E,5,0) | I36: =C36*H36 | K36: GRANEL | L36: =VLOOKUP(A36,MATERIALES!$A:$D,4,0) | M36: =L36*C36 | Z36: 2200 | AA36: =$O$3 | AB36: =IF(AA36<400,0,$O$3) | AD36: =IF(AB36<100,0,101) | AE36: =Z37-AA36 | AF36: =100-AE36 | AG36: =AE36
A37: 4000050 | B37: SUPER GRIDITO 7,800 KG GRIDO | C37: 4 | E37: =VLOOKUP(A37,MATERIALES!A531:D625,4,0) | F37: =E37*C37 | G37: =F37*1.21 | H37: =VLOOKUP(A37,MATERIALES!$A:$E,5,0) | I37: =C37*H37 | K37: GRANEL | L37: =VLOOKUP(A37,MATERIALES!$A:$D,4,0) | M37: =L37*C37 | Z37: 2300 | AA37: =$O$3 | AB37: =IF(AA37<400,0,$O$3) | AD37: =IF(AB37<100,0,101) | AE37: =Z38-AA37 | AF37: =100-AE37 | AG37: =AE37
A38: 4000071 | B38: TIRAMISU 7,800 KG GRIDO | C38: 0 | E38: =VLOOKUP(A38,MATERIALES!A532:D626,4,0) | F38: =E38*C38 | G38: =F38*1.21 | H38: =VLOOKUP(A38,MATERIALES!$A:$E,5,0) | I38: =C38*H38 | K38: GRANEL | L38: =VLOOKUP(A38,MATERIALES!$A:$D,4,0) | M38: =L38*C38 | Z38: 2400 | AA38: =$O$3 | AB38: =IF(AA38<400,0,$O$3) | AD38: =IF(AB38<100,0,101) | AE38: =Z39-AA38 | AF38: =100-AE38 | AG38: =AE38
A39: 4000055 | B39: TRAMONTANA 7,800 KG GRIDO | C39: 14 | E39: =VLOOKUP(A39,MATERIALES!A533:D627,4,0) | F39: =E39*C39 | G39: =F39*1.21 | H39: =VLOOKUP(A39,MATERIALES!$A:$E,5,0) | I39: =C39*H39 | K39: GRANEL | L39: =VLOOKUP(A39,MATERIALES!$A:$D,4,0) | M39: =L39*C39 | Z39: 2500 | AA39: =$O$3 | AB39: =IF(AA39<400,0,$O$3) | AD39: =IF(AB39<100,0,101) | AE39: =Z40-AA39 | AF39: =100-AE39 | AG39: =AE39
A40: 4000044 | B40: VAINILLA 7,800 KG GRIDO | C40: 10 | E40: 0.85 | F40: =E40*C40 | G40: =F40*1.21 | H40: =VLOOKUP(A40,MATERIALES!$A:$E,5,0) | I40: =C40*H40 | K40: GRANEL | L40: =VLOOKUP(A40,MATERIALES!$A:$D,4,0) | M40: =L40*C40 | Z40: 2600 | AA40: =$O$3 | AB40: =IF(AA40<400,0,$O$3) | AD40: =IF(AB40<100,0,101) | AE40: =Z41-AA40 | AF40: =100-AE40 | AG40: =AE40
A41: 4000163 | B41: PACK X6 GRIDO FAMILIAR X3LTS NRO 1 GRIDO | C41: 7 | D41: =SUM(C41:C44) | E41: =VLOOKUP(A41,MATERIALES!A535:D629,4,0) | F41: =E41*C41 | G41: =F41*1.21 | H41: =VLOOKUP(A41,MATERIALES!$A:$E,5,0) | I41: =C41*H41 | J41: 15 | K41: POTES 3L | L41: =VLOOKUP(A41,MATERIALES!$A:$D,4,0) | M41: =L41*C41 | Z41: 2700 | AA41: =$O$3 | AB41: =IF(AA41<400,0,$O$3) | AD41: =IF(AB41<100,0,101) | AE41: =Z42-AA41 | AF41: =100-AE41 | AG41: =AE41
A42: 4000164 | B42: PACK X 6 GRIDO FAMILIAR X3 LTS N2 GRIDO | C42: 12 | E42: =VLOOKUP(A42,MATERIALES!A536:D630,4,0) | F42: =E42*C42 | G42: =F42*1.21 | H42: =VLOOKUP(A42,MATERIALES!$A:$E,5,0) | I42: =C42*H42 | K42: POTES 3L | L42: =VLOOKUP(A42,MATERIALES!$A:$D,4,0) | M42: =L42*C42 | Z42: 2800
...

Sheet Hoja1
A1: B000302792 | B1: 4000065 | C1: 2 | D1: 0 | E1: 1000 | F1: 1004 | G1: Pedido WEB nro.1411479
A2: B000302792 | B2: 6002678 | C2: 1 | D2: 0 | E2: 1000 | F2: 1004 | G2: Pedido WEB nro.1411479
A3: B000302792 | B3: 6002672 | C3: 1 | D3: 0 | E3: 1000 | F3: 1004 | G3: Pedido WEB nro.1411479
A4: B000302792 | B4: 6002675 | C4: 1 | D4: 0 | E4: 1000 | F4: 1004 | G4: Pedido WEB nro.1411479
A5: B000302792 | B5: 6002712 | C5: 1 | D5: 0 | E5: 1000 | F5: 1004 | G5: Pedido WEB nro.1411479
A6: B000302792 | B6: 6003150 | C6: 1 | D6: 0 | E6: 1000 | F6: 1004 | G6: Pedido WEB nro.1411479
A7: B000302792 | B7: 4000670 | C7: 3 | D7: 0 | E7: 1000 | F7: 1004 | G7: Pedido WEB nro.1411479
A8: B000302792 | B8: 4000341 | C8: 2 | D8: 0 | E8: 1000 | F8: 1004 | G8: Pedido WEB nro.1411479
A9: B000302792 | B9: 4000152 | C9: 2 | D9: 0 | E9: 1000 | F9: 1004 | G9: Pedido WEB nro.1411479
A10: B000302792 | B10: 4000162 | C10: 2 | D10: 0 | E10: 1000 | F10: 1004 | G10: Pedido WEB nro.1411479
A11: B000302792 | B11: 4000160 | C11: 5 | D11: 0 | E11: 1000 | F11: 1004 | G11: Pedido WEB nro.1411479
A12: B000302792 | B12: 4000153 | C12: 3 | D12: 0 | E12: 1000 | F12: 1004 | G12: Pedido WEB nro.1411479
... A73: B000302792 | B73: 6002671 | C73: 2 | D73: 0 | E73: 1000 | F73: 1004 | G73: Pedido WEB nro.1411479

Sheet franquicias
A1: Klappen | B1: Titular FACTURABLE
A2: 100271-1 | B2: CABRERA, GUSTAVO RAFAEL
A3: 100696-3 | B3: PROGRESO J&T S.A.
A4: 100375 | B4: LIZONDO, MARIA GRACIELA
A5: 100144 | B5: BOSCO, HECTOR JAVIER
A6: 100143 | B6: SALVADOR, FERRER ALVAREZ
A7: 100697-1 | B7: OCTI S.R.L.
A8: 101051-1 | B8: CORDOBA HELADERIAS S.A.S.
A9: 100279 | B9: ROSSI, LUCIANO BENJAMIN
A10: 100621 | B10: LUCCRA S.A.
A11: 100621-2 | B11: LUCCRA S.A.
A12: 101191 | B12: VILLALBA PAULA MARIELA
A13: 101384 | B13: HERNANDEZ CASASOLA MARIA EUGEN
A14: 100147 | B14: LONDERO, MAURO SEBASTIAN
A15: 100684 | B15: RETIA S.R.L
A16: 100419 | B16: ESCALANTE PAZ, MARIA FERNANDA
A17: 100247-1 | B17: CHAILE HERNAN NICOLAS
A18: 100964 | B18: ODETTI, LUCIANA LAURA
A19: 100413 | B19: PALAT, KARINA MARIEL
A20: 101092 | B20: WAIGEL, JEREMIAS NAHUEL
A21: 100732-1 | B21: MANOLETE Y MANOLETA S.R.L.
A22: 100731 | B22: LA TOTO S.R.L.
A23: 101111 | B23: LOPEZ LORENA RAQUEL
A24: 100003 | B24: RODRIGUEZ, JUAN DOMINGO
A25: 101051-2 | B25: CORDOBA HELADERIAS S.A.S.
A26: 100697-4 | B26: OCTI S.R.L.
A27: 100896-1 | B27: HELADOS SAN VICENTE S.R.L.
A28: 100656-3 | B28: GENKO S.A.
A29: 100510 | B29: GARCIA, VERONICA EVANGELINA
A30: 100213 | B30: ZACHARSKI, JORGE MATIAS
A31: 100288 | B31: HEREDIA D´AGOSTINO, MATIAS
A32: 100732 | B32: MANOLETE Y MANOLETA S.R.L.
A33: 100696-4 | B33: PROGRESO J&T S.A.
A34: 100634 | B34: USHPA S.R.L.
A35: 100701-1 | B35: GRUPO ABG S.R.L.
A36: 101292 | B36: GOTAMA S.A.S.
A37: 100472 | B37: RODRIGUEZ VAGLIERA, LORENA VAN
A38: 100031 | B38: PEREYRA, LUIS ANGEL
A39: 101204 | B39: MERCADO ADRIAN ENRIQUE
A40: 100102 | B40: ZAMPETTI, MARCELO RAFAEL
...

Sheet MATERIALES
A1: Codigo | B1: Deposito | C1: Descripcion | D1: Cubicaje | E1: Peso | F1: impuestoIva | G1: precio
A2: 4000050 | B2: 1000;1004 | C2: SUPER GRIDITO 7,800 KG GRIDO | D2: 0.8 | E2: 7.8 | F2: 0 | G2: 4998.53 | H2: 100 | I2: 110 | J2: =H2*D2/I2
A3: 4000044 | B3: 1000;1004 | C3: VAINILLA 7,800 KG GRIDO | D3: 0.8 | E3: 7.8 | F3: 0 | G3: 4998.53 | H3: 100 | I3: 110 | J3: =H3*D3/I3
A4: 4000036 | B4: 1000;1004 | C4: LIMON AL AGUA 7,800 KG GRIDO | D4: 0.8 | E4: 7.8 | F4: 0 | G4: 2706.22 | H4: 100 | I4: 110 | J4: =H4*D4/I4
A5: 4000042 | B5: 1000;1004 | C5: FRUTILLA A LA CREMA 7,800KG GRIDO | D5: 0.8 | E5: 7.8 | F5: 0 | G5: 4998.53 | H5: 100 | I5: 110 | J5: =H5*D5/I5
A6: 4000056 | B6: 1000;1004 | C6: KINOTOS AL WHISKY 7,800 KG GRIDO | D6: 0.8 | E6: 7.8 | F6: 0 | G6: 5461.98 | H6: 100 | I6: 110 | J6: =H6*D6/I6
A7: 4000043 | B7: 1000;1004 | C7: CHOCOLATE 7,800 KG GRIDO | D7: 0.8 | E7: 7.8 | F7: 0 | G7: 4998.53 | H7: 100 | I7: 110 | J7: =H7*D7/I7
A8: 4000061 | B8: 1000;1004 | C8: CHOCOLATE MANI CRUNCH 7,800 KG GRIDO | D8: 0.8 | E8: 7.8 | F8: 0 | G8: 5461.98 | H8: 100 | I8: 110 | J8: =H8*D8/I8
A9: 4000068 | B9: 1000;1004 | C9: DULCE LECHE C/NUEZ 7,800 KG GRIDO | D9: 0.8 | E9: 7.8 | F9: 0 | G9: 6079.84 | H9: 100 | I9: 110 | J9: =H9*D9/I9
A10: 4000045 | B10: 1000;1004 | C10: CREMA AMERICANA 7,800 KG GRIDO | D10: 0.8 | E10: 7.8 | F10: 0 | G10: 4998.53 | H10: 100 | I10: 110 | J10: =H10*D10/I10
A11: 4000047 | B11: 1000;1004 | C11: FLAN 7,800 KG GRIDO | D11: 0.8 | E11: 7.8 | F11: 0 | G11: 4998.53 | H11: 100 | I11: 110 | J11: =H11*D11/I11
A12: 4000048 | B12: 1000;1004 | C12: BANANA C/DULC LECHE 7,800 KG GRIDO | D12: 0.8 | E12: 7.8 | F12: 0 | G12: 4998.53 | H12: 100 | I12: 110 | J12: =H12*D12/I12
A13: 4000049 | B13: 1000;1004 | C13: MENTA GRANIZADA 7,800 KG GRIDO | D13: 0.8 | E13: 7.8 | F13: 0 | G13: 4998.53 | H13: 100 | I13: 110 | J13: =H13*D13/I13
... A80: 6002671 | B80: 1000;1004 | C80: PACK 12 CAJAS PIZZA FRIZZIO 510 grs. | D80: 0.76363636 | E80: 0.51 | F80: 0 | G80: 8496.21 | H80: 100 | I80: 110 | J80: =H80*D80/I80
A81: 6002672 | B81: 1000;1004 | C81: PACK 16 UN. BASTONCITOS FRIZZIO 380 grs | D81: 0.94727273 | E81: 6.08 | F81: 0 | G81: 10653.3 | H81: 100 | I81: 110 | J81: =H81*D81/I81 | K81: =J81*12
A82: 6002673 | B82: 1000;1004 | C82: PACK 16 PECHUGUITA FRIZZIO 380 grs | D82: 1.0818182 | E82: 6.08 | F82: 0 | G82: 9611.78 | H82: 100 | I82: 110 | J82: =H82*D82/I82
A83: 6002674 | B83: 1000;1004 | C83: PACK 20 UN. MINI PIZZA FRIZZIO X 180 grs | D83: 0.94727273 | E83: 3.6 | F83: 0 | G83: 6877.24 | H83: 100 | I83: 110 | J83: =H83*D83/I83
A84: 6002675 | B84: 1000;1004 | C84: PACK 12 PIZZAS INTEGRAL FRIZZIO 530 grs. | D84: 1.2627273 | E84: 6.36 | F84: 0 | G84: 8742 | H84: 100 | I84: 110 | J84: =H84*D84/I84
A85: 6002676 | B85: 1000;1004 | C85: PACK 72 EMPANADAS DE CARNE DE 70 grs. | D85: 1.2627273 | E85: 5.04 | F85: 0 | G85: 7805.27 | H85: 100 | I85: 110 | J85: =H85*D85/I85
A86: 6002677 | B86: 1000;1004 | C86: PACK 72 EMPANADAS DE JyQ DE 70 grs. | D86: 1.0327273 | E86: 5.04 | F86: 0 | G86: 8313.5 | H86: 100 | I86: 110 | J86: =H86*D86/I86
A87: 6002678 | B87: 1000;1004 | C87: PACK 11 PIZZAS DE CEBOLLA FRIZZIO 540 gr | D87: 1.2627273 | E87: 5.94 | F87: 0 | G87: 7724.86 | H87: 100 | I87: 110 | J87: =H87*D87/I87
A88: 6002679 | B88: 1000;1004 | C88: PACK 11 PIZZAS DE JAMON FRIZZIO 535 grs. | D88: 1.2627273 | E88: 5.88 | F88: 0 | G88: 8619 | H88: 100 | I88: 110 | J88: =H88*D88/I88
A89: 6002680 | B89: 1000;1004 | C89: PACK X 8 PIZZA FRIZZIO T. CASERA 665 grs | D89: 1.2627273 | E89: 5.32 | F89: 0 | G89: 8311.9 | H89: 100 | I89: 110 | J89: =H89*D89/I89
A90: 6002681 | B90: 1000;1004 | C90: CAPUCHON SUNDAE GO SHOT X 70 UN | D90: 1.0818182 | E90: 0.01 | F90: 0 | G90: 9268.42 | H90: 100 | I90: 110 | J90: =H90*D90/I90
A91: 6002682 | B91: 1000;1004 | C91: PACK X 6 POSTRE CREMOSO - TIRAMISU | D91: 0.99909091 | E91: 4.5 | F91: 0 | G91: 8449.29 | H91: 100 | I91: 110 | J91: =H91*D91/I91
A92: 6002683 | B92: 1000;1004 | C92: PACK X 6 POSTRE CREMOSO - LEMON PIE | D92: 0.99909091 | E92: 4.5 | F92: 0 | G92: 8449.29 | H92: 100 | I92: 110 | J92: =H92*D92/I92
A93: 6002684 | B93: 1000;1004 | C93: PACK X 6 POSTRE CREMOSO- CREM DE CHOCOL. | D93: 0.99909091 | E93: 4.5 | F93: 0 | G93: 8449.29 | H93: 100 | I93: 110 | J93: =H93*D93/I93
... A128: 6002844 | B128: 1000;1004 | C128: MUFFIN CHOCOLATE X 10 UN FUDY | D128: 1.8181818 | E128: 1.35 | F128: 0 | G128: 3074.59 | H128: 100 | I128: 110 | J128: =H128*D128/I128
A129: 6002845 | B129: 1000;1004 | C129: PACK 18 VIANDA POLLO AL DISCO C/VEG | D129: 0 | F129: 0 | G129: 10333 | H129: 100 | I129: 110 | J129: =H129*D129/I129
A130: 6002846 | B130: 1000;1004 | C130: VIANDA X 18 MILANESAS CON PURE | D130: 1.2981818 | E130: 9.6 | F130: 0 | G130: 10333 | H130: 100 | I130: 110 | J130: =H130*D130/I130
A131: 6002848 | B131: 1000;1004 | C131: PACK 24 VIANDAS PASTEL DE PAPAS | D131: 1.2981818 | E131: 9.6 | F131: 0 | G131: 14555.74 | H131: 100 | I131: 110 | J131: =H131*D131/I131
A132: 6002849 | B132: 1000;1004 | C132: PACK 24 VIANDAS CANELONES DE CARNE | D132: 1.5090909 | E132: 10.8 | F132: 0 | G132: 14555.74 | H132: 100 | I132: 110 | J132: =H132*D132/I132
A133: 6002850 | B133: 1000;1004 | C133: PACK 24 VIAN. LASAG DE C. C/ ESPINACA NR | D133: 1.2981818 | E133: 10.8 | F133: 0 | G133: 13166.17 | H133: 100 | I133: 110 | J133: =H133*D133/I133
A134: 6002851 | B134: 1000;1004 | C134: PACK 24 VIANDA LASAGNA BOLOG. CON JYQ NR | D134: 1.2981818 | E134: 10.8 | F134: 0 | G134: 13166.17 | H134: 100 | I134: 110 | J134: =H134*D134/I134
A135: 6002854 | B135: 1000;1004 | C135: BUDIN LIMON C/ AMAPOLA X 20 UN FUDY | D135: 1.8181818 | E135: 1.8 | F135: 0 | G135: 4853 | H135: 100 | I135: 110 | J135: =H135*D135/I135
A136: 6002858 | B136: 1000;1004 | C136: PACK X 18 PAPAS MACCAI NOSETTE X 500 GRS | D136: 1.01 | E136: 9 | F136: 0 | G136: 7861.44 | H136: 100 | I136: 110 | J136: =H136*D136/I136
A137: 6002804 | B137: 1000;1004 | C137: PACK 12 PAPAS SMILE MCAIN 600 GR | D137: 1.01 | E137: 7.2 | F137: 0 | G137: 10424.3 | H137: 100 | I137: 110 | J137: =H137*D137/I137
A138: COMBO MIX PIZZA 50% | B138: 1000;1004 | C138: COMBO MIX PIZZA 50% | D138: 6.7618182 | E138: 27.61 | F138: 0 | G138: 343310.36 | H138: 100 | I138: 110 | J138: =H138*D138/I138
A139: COMBO PIZZA 100% | B139: 1000;1004 | C139: COMBO MIX PIZZA 100% | D139: 6.7618182 | E139: 27.61 | F139: 0 | G139: 692726.61 | H139: 100 | I139: 110 | J139: =H139*D139/I139
A140: 4000440 | B140: 1000;1004 | C140: PALITO AGUA SABOR FRUTILLA VB C. x 80UN | D140: 0.84181818 | E140: 4.4 | F140: 0 | G140: 2472.21 | H140: 100 | I140: 110 | J140: =H140*D140/I140
...

Sheet LISTA Z1
A1: 4000036 | B1: LIMON AL AGUA 7,800 KG GRIDO | C1: 10232.17
A2: 4000038 | B2: MARACUYA AL AGUA 7,800 KG GRIDO | C2: 10232.17
A3: 4000039 | B3: NARANJA AL AGUA 12 7,800 KG GRIDO | C3: 10232.17
A4: 4000040 | B4: GRANIZADO 7,800 KG GRIDO | C4: 19297.96
A5: 4000041 | B5: DULCE DE LECHE 7,800 KG GRIDO | C5: 19297.96
A6: 4000042 | B6: FRUTILLA A LA CREMA 7,800KG GRIDO | C6: 19297.96
A7: 4000043 | B7: CHOCOLATE 7,800 KG GRIDO | C7: 19297.96
A8: 4000044 | B8: VAINILLA 7,800 KG GRIDO | C8: 19297.96
A9: 4000045 | B9: CREMA AMERICANA 7,800 KG GRIDO | C9: 19297.96
A10: 4000046 | B10: DULCE LECHE GRANIZADO 7,800 KG GRIDO | C10: 19297.96
A11: 4000047 | B11: FLAN 7,800 KG GRIDO | C11: 19297.96
A12: 4000048 | B12: BANANA C/DULC LECHE 7,800 KG GRIDO | C12: 19297.96
... A108: 6002857 | B108: PACK 4 CAJAS POSTRE VEGANO MANI - GR | C108: 22786.28

Sheet multiplos 
A1: FAMILIAS | B1: PRODUCTOS | C1: BASES | D1: PORCENTAJE BASE
A2: GRANEL | B2: TODOS | C2: 25 | D2: 20
A3: POTES 3L | B3: TODOS | C3: 15 | D3: 16.35
A4: TORTAS | B4: TODOS | C4: 10 | D4: 12
A5: TENTACIÓN | B5: TODOS | C5: 15 | D5: 7.5818182
A6: PALITOS | B6: TODOS | C6: 15 | D6: 12.3
A7: ESCOCES-SHOT | B7: ESCOCES-SHOT | C7: 10 | D7: 7.7
A8: PORCIÓN | B8: ALMENDRADO- SUIZO- CASATTA | C8: 10 | D8: 7.7
A9: BARRAS | B9: DELICIA-CROCANTINO-VAINILLA SPLIT-CROCANTE | C9: 12 | D9: 6.9927273
A10: ALIMENTOS CONGELADOS | B10: TODOS | C10: 9 | D10: 14
